Workbook

Sheet Page d'accueil
E8: Fonds d'aide au jeu vidéo
E9: Aide à l'écriture
E11: Cette aide a pour vocation d'accompagner l’élaboration de la bible de conception d’un jeu vidéo (couramment appelée game design document) présentant toutes les caractéristiques du jeu à venir : mécaniques de jeux, éléments scénaristiques, bible graphique, principes de programmation et autres spécifications techniques.
E15: Les auteurs déposants ont, soit la nationalité française, soit sont ressortissants d'un Etat de l'union européenne ou d'un Etat ayant conclu des accords dans le secteur audiovisuel. Voir la liste :
E17: https://www.coe.int/en/web/conventions/cets-number-/-abridged-title-known?module=signatures-by-treaty&treatynum=132
E19: Au moins l’un des auteurs déposants justifie d'une formation spécifique dans le domaine du jeu vidéo ou d’une expérience significative dans l’équipe de création d’un jeu vidéo mis à disposition du public à titre onéreux ou gratuit.
E22: ► L'éligibilité via la formation : seules les formations diplômantes de création/conception jeu vidéo sont éligibles (game design, game art, narrative design, level design, programmation etc.)
E25: ► L'éligibilité via l'expérience : seules les expériences professionnelles directement liées à la création/conception de jeu vidéo édités commercialement sont éligibles.
E29: Les auteurs déposants doivent être les seuls concepteurs du projet qu’ils soumettent, en disposer de tous les droits et être en capacité de le présenter (ne pas avoir signé un contrat de cession des droits ou d'exclusivité de cette œuvre à un studio / producteur / éditeur ; avoir l'accord des ayants droits en cas d'adaptation, etc.)
E33: L'aide est réservée aux créateurs indépendants, c’est-à-dire des personnes physiques non liées à une société.
E34: ► L'aide est ouverte aux artistes-auteurs, entrepreneurs individuels, etc.
E35: ► Les salariés d'une société de jeu vidéo peuvent déposer une demande à condition de fournir une attestation de leur employeur certifiant qu'il s'agit d'un projet personnel fait sur temps libre non développé par la société et, qu'en ce sens, la société ne sollicitera pas le FAJV et le CIJV pour le projet.
... E42: <!> Dans le cas d'une première demande ou pour toute question, il est recommandé de nous contacter au moins 3 semaines avant le dépôt souhaité.
E43: Voir le calendrier des dépôts : | H43: https://www.cnc.fr/professionnels/aides-et-financements/jeu-video/fonds-daide-au-jeu-video-fajv_191468
E45: Direction du numérique - service de la création numérique
E46: Accueil et information des porteurs de projet / dépôts et résultats de commissions
E48: Chargée de mission - Alexandra Cola | Q48: ( | R48: 01 44 34 34 12 / @ alexandra.cola@cnc.fr
E50: Cheffe de service adjointe - Juliette Berthier
E51: Chef de service - Olivier Fontenay
E53: Le dossier complet au format numérique doit être adressé par mail à : commission-fajv@cnc.fr

Sheet 0_Dossier de demande 
M2: FAJV Demande d'aide à l'écriture
D4: Il est impératif de respecter strictement les consignes ci-après
C6: A1 - | D6: DOSSIER ADMINISTRATIF (1 fichier PDF nommé comme suit: A1_titreduprojet_dossier administratif)
D8: (Toutes les feuilles du fichier excel sont à compléter et à parapher)
F10: 1- | G10: Lettre de demande
F12: 2- | G12: Fiche de présentation du projet
F14: 3- | G14: Fiche de renseignements concernant les auteurs
F16: 4- | G16: Accord de répartition entre les auteurs
F18: 5 - | G18: Devis prévisionnel et plan de financement
F20: 6 - | G20: Fiche de synthèse
C23: A2 - | D23: JUSTIFICATIFS à fournir (1 fichier PDF nommé comme suit: A2_titreduprojet_justificatifs)
F25: 1- | G25: Le(s) curriculum vitae - CV à jour et clair concernant les statuts (freelance, salariés…)
F27: 2- | G27: Le(s) justicatif(s) d'éligiblité - Diplôme d'une formation jeu vidéo ; tout document attestant une expérience professionnelle dans l'équipe créative d'un jeu édité.
F29: 3- | G29: Le(s) justificatif(s) d'un financement inscrit au plan de financement - Relevé(s) de compte pour les apports personnels numéraires
F31: 4- | G31: La copie recto/verso d'une pièce d'identité de chaque auteur - CNI, passeport ou titre de séjour européen d'au moins 10 ans de validité.
F33: 5- | G33: Le Relevé d'idendité Bancaire original de chaque auteur - RIB personnel avec prénom et nom conformément écrits et identiques à la pièce d'identité.
C38: B1 - | D38: DOSSIER ARTISTIQUE (1 fichier PDF nommé comme suit: B_titreduprojet_dossier artistique)
D40: (PDF de 12 pages / 20Mo maximum, pour tous compléments visuels nécessaires à une meilleure appréciation artistique du projet, un lien ou plusieurs liens hypertextes peuvent etre intégrés au fichier pdf)
F43: 1- | G43: Une présentation synthétique (1 page) des principaux éléments du projet : titre, genre, univers, public cible, plateforme, outils, méthodologie
F45: 2- | G45: Note d'intention des auteurs décrivant la genèse du projet, les différents profils composant l'équipe de création et les principaux enjeux créatifs du jeu
F47: 3- | G47: Un dossier littéraire et graphique décrivant les principales caractéristiques du jeu:
G48: - concept
G50: - principales mécaniques de jeu
G52: - recherches visuelles et graphiques
G54: - éléments scénaristiques (le cas échéant)
G56: - note technique
F57: 4- | G57: Une note d'intention "IA" en cas d'utilisation d'outils intelligence artificielle générative
G58: Une attention particulière est portée à l'utilisation d'outils d'intelligence artificielle qui sont susceptibles d'impacter le processus de création ou de fabrication de l'œuvre, compte tenu des risques inhérents à cette technologie. Les porteurs de projets concernés sont ainsi invités à communiquer des éléments qui concernent :
G60: - la valeur ajoutée artistique de l'utilisation de l’IA
G61: - la mention des outils utilisés et la justification de ces choix techniques
G62: - l'évaluation des enjeux juridiques
G63: - l'évaluation de l'impact potentiel sur la stratégie de production (taille de l'équipe, organisation du travail, enjeux budgétaires)
F65: 5- | G65: Un état des recherches de partenaires artistiques et financiers éventuels
F67: 6- | G67: Un calendrier prévisionnel de réalisation.
D69: La liste des éléments artistiques ci-dessus est donnée à titre indicatif au regard de ce qui est généralement attendu par la commission à ce stade.
D70: Vous pouvez adapter le dossier en fonction des spécificités de votre projet. Présentez-le de la manière la plus claire et la plus valorisante possible !
D71: A toutes fins utiles, vous pouvez consulter la scénariothèque jeu vidéo du CNC comprenant des projets lauréats à l'écriture et ainsi comprendre les attentes de la commission.
C73: B2 - | D73: COMPLEMENTS ARTISTIQUES optionnels (1 fichier PDF nommé comme suit: B2_titreduprojet_compléments visuels)
G75: - | H75: Vidéos : liens sécurisés
G76: - | H76: Images : format jpeg/gif
...

Sheet 1_Lettre de demande
L2: 1 - Lettre de demande
B6: Monsieur le président
B8: Je (nous) soussigné(ons) en qualité d'auteur(s)
B12: sollicite(ons) auprès du Centre national du cinéma et de l'image animée, pour le projet intitulé :
B14: le versement d'une aide à l'écriture d'un montant de : | O14: €
B18: Je (nous) certifie(ons) par la présente être le(s) seul(s) auteur(s) de cette œuvre et garantis(sons) le Centre national du cinéma et de l'image animée contre tout recours que pourrait faire à son encontre tout personne qui prétendrait détenir des droits sur ladite œuvre ou sur l'aide qui pourrait nous être accordée. En l'espèce, je (nous) certifie(ons) que le projet ne fait pas l'objet d'un contrat de cession des droits ou/et d'exclusivité avec un studio, un producteur, ou un éditeur et ce jusqu'à la signature de la convention, en cas d'avis favorable de la commission.
B20: Je (nous) certifie(ons) par la présente ne pas avoir utilisé un programme d'intelligence artificielle générative pour la rédaction du dossier de demande ainsi que la rédaction du dossier de rendu en cas d'octroi de l'aide. Je (nous) certifie(ons) par la présente avoir bien crédité le programme utilisé en cas de génération de visuels via intelligence artificielle pour la direction artistique du jeu.
B25: Je (nous) déclare(ons) avoir pris connaissance de l'article 441-6 alinéa 2 du Code pénal qui stipule que "le fait de fournir une déclaration mensongère
B26: en vue d’obtenir d’une administration publique ou d’un organisme chargé d’une mission de service public une allocation, un paiement ou un avantage
B27: indu est puni de deux ans d’emprisonnement et de 30 000 € d’amende », et certifie(ons) l’exactitude de l’ensemble des renseignements
B28: fournis dans ce dossier.
B31: Date, signature de chaque auteur :
K45: Impérativement co-signée par tous les auteur(s) déposants

Sheet 2_Fiche projet
I2: 2 - Fiche projet : présentation
B5: TITRE DU PROJET:
B7: GENRE (aventure, réflexion, stratégie etc.) :
B9: PLATEFORME(S) (PS5, PC, Mobile IOS/Android etc.):
B11: MULTIJOUEUR: | M11: OUI | S11: NON
B13: Modèle de commercialisation (free-to-play, pay-to-play etc.):
B15: Plateforme(s) de distribution (Steam, PSN, Apple Arcade etc.):
B17: Type de joueur (casual, midcore, hardcore) :
B19: Public ciblé (enfants, adolescents/jeunes adultes, tout public) :
B21: Prévision de classification du projet (modèle PEGI) : | M21: __ ans
B23: Contact (mail) de l'auteur responsable du projet : Pourra être diffusé par le CNC en cas de sélection du projet
B28: RESUME DU PROJET
B29: Sera diffusé par le CNC en cas de sélection du projet
B38: APERCU GRAPHIQUE DU PROJET : Image créée spécifiquement pour le projet, dont vous avez les droits, qui pourra être diffusée par le CNC en cas de sélection du projet. Optionnel, ne pas compléter s'il n'existe pas encore de visuel propre au projet.
B45: Je (nous) autorise(ons) la libre diffusion par le CNC des informations précitées, par courriel auprès des professionnels du secteur (auteurs, producteurs etc.), sur le site internet du CNC et sur tout support de communication dédié au Fonds d’aide au Jeu Vidéo du CNC en cas d’obtention d’une aide à l’écriture*.
B49: En cas d’obtention d’une aide à l’écriture, je (nous) autorise(ons) la libre diffusion sur le site internet (scénariothèque) du CNC des dossiers artistiques de demande et de remise de la version retravaillée du projet**.
B52: Date et signature de chacun des auteurs:
B65: *Dans le cas contraire, le contact mail pour le projet n’apparaîtra pas sur le site du CNC et ne sera pas publié.
B66: **Les auteurs seront systématiquement prévenus de la mise en ligne du projet concerné.

Sheet 3_Fiche auteurs 
K2: 3 - Renseignements concernant les auteurs
B5: NOM / Prénom
B6: QUALITE
J7: Game designer | T7: graphiste | AA7: scénariste | AI7: Programmeur.euse
J9: Autre | R9: Préciser >
B11: TELEPHONE
B12: E-MAIL
B13: NATIONALITE
B14: DATE DE NAISSANCE
B15: ADRESSE
B16: REGION
B18: NOM / Prénom
B19: QUALITE
J20: Game designer | T20: graphiste | AA20: scénariste | AI20: Programmeur.euse
J22: Autre | R22: Préciser >
B24: TELEPHONE
B25: E-MAIL
B26: NATIONALITE
B27: DATE DE NAISSANCE
B28: ADRESSE
B29: REGION
B31: NOM / Prénom
B32: QUALITE
J33: Game designer | T33: graphiste | AA33: scénariste | AI33: Programmeur.euse
J35: Autre | R35: Préciser >
B37: TELEPHONE
B38: E-MAIL
B39: NATIONALITE
B40: DATE DE NAISSANCE
B41: ADRESSE
B42: REGION
B44: NOM / Prénom
B45: QUALITE
J46: Game designer | T46: graphiste | AA46: scénariste | AI46: Programmeur.euse
J48: Autre | R48: Préciser >
B50: TELEPHONE
B51: E-MAIL
B52: NATIONALITE
B53: DATE DE NAISSANCE
B54: ADRESSE
...

Sheet 4_Accord répartition
N2: 4 - Accord de répartition des auteurs
C5: Entre les soussignés :
C7: Prénom NOM auteur 1, Prénom NOM auteur 2, Prénom NOM auteur 3, Prénom NOM auteur 4, Prénom NOM auteur 5
C10: Etant préalablement rappelé que :
C11: Les soussignés ont présenté conjointement au Centre national du cinéma et de l'image animée une demande d'aide à l'écriture de jeu vidéo
C12: pour le projet intitulé :
C14: Il est convenu et arrêté que :
C15: L'aide versée par le Centre national du cinéma et de l'image animée sera répartie entre les soussignés de la façon suivante :
B17: - | G17: % | H17: (nombre en lettres) pour | P17: Prénom NOM auteur 1
B19: - | G19: % | H19: (nombre en lettres) pour | P19: Prénom NOM auteur 2
B21: - | G21: % | H21: (nombre en lettres) pour | P21: Prénom NOM auteur 3
B23: - | G23: % | H23: (nombre en lettres) pour | P23: Prénom NOM auteur 4
B25: - | G25: % | H25: (nombre en lettres) pour | P25: Prénom NOM auteur 5
C27: *Le total doit bien faire 100% (cent pour cent)
C28: Tous les auteurs déposants doivent figurer dans la répartition et être rémunérés
AC30: Fait à | AM30: , le
C32: Signatures des auteurs :

Sheet 5_Budget et financement
J2: 5 - Budget et plan de financement
B4: ⚠ | C4: L'aide à l'écriture soutient la phase de conception du jeu, seules les dépenses liées directement et spécifiquement à la création "artistique" du projet sont éligibles.
C5: Des frais de création d'entreprise, de marketing, de mise en page ou bien l'achat d'un ordinateur ne sont pas éligibles par exemple.
B7: Dépenses à engager (devis prévisionnel) travail d'écriture, travail graphique, recherches, matériel etc. | X7: Total
B9: exemples :
B10: auteur 1 : travail d'écriture | O10: Lore
O11: scénario - embranchements
O12: dialogues
B13: auteur 2 : travail graphique | O13: univers visuel - DA
O14: chara design
B15: auteur 3 : programmation | O15: tests gameplay et systèmes de jeu
B16: Frais licences informatique et abonnements | O16: adobe
B17: Frais recherches historiques | O17: consultant.e externe
B19: TOTAL | X19: =SUM(X9:X18) -> 0
B21: Financements acquis et/ou sollicités | X21: Total
B23: CNC - aide à l'écriture FAJV | O23: en cours
O25: Acquis
O27: à solliciter
B29: TOTAL | X29: =SUM(X23:X28) -> 0
B31: Il s'agit ici du budget prévisionnel de la phase d'écriture/conception. A ce stade, il est possible que l'aide du CNC soit le seul financement identifié.
B32: Seules les sommes numéraires sont prises en compte (pas d'apport en industrie)
B33: Le total du plan de financement doit bien correspondre au total des dépenses, la demande auprès du CNC ne peut en aucun cas dépasser les dépenses.

Sheet 6_Fiche synthèse
D2: 6 - Fiche de synthèse
C7: A quoi va servir cette fiche de synthèse :
C8: - Elle a pour but de visualiser et comprendre synthétiquement votre projet
C9: - Elle sera projetée lors de la commission, au moment de l’examen du projet,
C10: pour en rappeler les principales caractéristiques
C11: - Elle pourra être utilisée lors de réunions internes au CNC concernant la préparation
C12: de la commission ou le suivi des projets
C13: - Si le projet fait l'objet d'un soutien, elle pourra être montrée à des organismes publics (Ministère, DRAC…)
C14: dans le cadre du suivi des projets mais ne sera pas diffusée publiquement
C15: - Le cas échéant, toute autre utilisation fera l’objet d’une demande d’autorisation préalable
C19: Consignes pour compléter la fiche:
C20: - Renseigner UNIQUEMENT le résumé du projet et insérer un ou plusieurs visuels (avec la source)
C21: - les autres éléments ont été complétés automatiquement grâce aux informations indiquées dans les autres onglets
... C28: Nous nous réservons le droit de modifier la forme de votre fiche afin d’assurer une meilleure lisibilité
C49: ='2_Fiche projet'!G5 -> 0
C51: • Montant demandé : | D51: ='1_Lettre de demande'!N14 -> 0
C52: • Devis écriture: | D52: ='5_Budget et financement'!X19 -> 0
C53: • Plateformes : | D53: ='2_Fiche projet'!M9 -> 0
C54: • Type de jeu (genre) : | D54: ='2_Fiche projet'!M7 -> 0
C55: • Auteurs : | D55: ='3_Fiche auteurs '!I5 -> 0
D56: ='3_Fiche auteurs '!I18 -> 0
D57: ='3_Fiche auteurs '!I31 -> 0
D58: ='3_Fiche auteurs '!I44 -> 0
D59: ='3_Fiche auteurs '!I57 -> 0
H61: Insérez dans ce cadre le ou les visuels illustrant le mieux votre projet
C62: Résumé du projet :
C63: Ces quelques lignes doivent faire ressortir les principales caractéristiques du jeu
H87: Source des images: images originales / images générées par IA / images de référence non originales

Sheet Results
AB2: Résultats
AB4: Entreprise : | AE4: ='1_Lettre de demande'!J10 -> 0
AB6: Jeu vidéo : | AE6: ='1_Lettre de demande'!#REF! -> #REF!
AB8: I - BAREME "Auteurs et collaborateurs de création" | BB8: Barème de points pour information | BL8: Points obtenus | BP8: Réservé au CNC
AB10: Directeur créatif ou réalisateur | BC10: 3 | BM10: =IF(BW10=TRUE,3,0) -> 0 | BW10: FALSE | BX10: FALSE
AB12: Responsable de la conception des mécanismes du jeu | BC12: 3 | BM12: =IF(BW12=TRUE,3,0) -> 0 | BW12: FALSE
AB14: Scénariste | BC14: 2 | BM14: =IF(BW14=TRUE,2,0) -> 0 | BW14: FALSE
AB16: Directeur artistique | BC16: 2 | BM16: =IF(BW16=TRUE,2,0) -> 0 | BW16: FALSE
AB18: Compositeur musique ou créateur environnement sonore | BC18: 1 | BM18: =IF(BW18=TRUE,1,0) -> 0 | BW18: FALSE
AB20: Equipe de création : | BW20: FALSE
AC22: Masse salariale en France et en Europe : | AQ22: =#REF! -> #REF!
AC24: Masse salariale hors France et Europe : | AQ24: =#REF! -> #REF!
AC26: Total de la masse salariale : | AQ26: =AQ22+AQ24 -> #REF!
AC28: 2/3 des dépenses salariales réalisées en France et en Europe | AQ28: =(AQ26*2)/3 -> #REF! | BC28: 9 | BM28: =IF(BW28=TRUE,9,0) -> 0 | BW28: FALSE
AB31: Total Bareme "Auteurs et collaborateurs de création" | BM31: =BM10+BM12+BM14+BM16+BM18+BM28 -> 0 | BQ31: =BQ10+BQ12+BQ14+BQ16+BQ18+BQ28 -> 0
AB34: II - CRITERES "Contribution au développement de la création" | BB34: Barème de points pour information | BL34: Points obtenus | BP34: Réservé au CNC
AB36: Création d'origine patrimoniale
AC38: ­ Le jeu est inspiré d'une œuvre reconnue du patrimoine, artistique et scientifique européen.
AC40: Laquelle : | AF40: =#REF! -> #REF! | BC40: 4 | BM40: =IF(BW40=TRUE,4,0) -> 0 | BW40: FALSE
AB42: OU
AC43: ­ Le jeu est adapté d'une œuvre cinématographique, audiovisuelle, littéraire, artistique ou d'une bande dessinée.
AC45: Laquelle : | AF45: =#REF! -> #REF! | BC45: 2 | BM45: =IF(BW45=TRUE,2,0) -> 0 | BW45: FALSE
AB47: Originalité de la création | BC47: 2 | BM47: =IF(BW47=TRUE,2,0) -> 0 | BW47: FALSE
AB49: Contenus culturels
AC51: ­ Le jeu repose sur une narration | BC51: 3 | BM51: =IF(BW51=TRUE,3,0) -> 0 | BW51: FALSE
AC53: ­ Les dépenses artistiques représentent plus de 50% du coût de développement : | BC53: 2 | BM53: =IF(BW53=TRUE,2,0) -> 0 | BW53: FALSE
AD55: Montant des dépenses artistiques : | AL55: 0
AD57: Coût total de développement : | AL57: =#REF! -> #REF!
AD59: Pourcentage : | AL59: =AL55/AL57 -> #REF!
AC61: ­ La version originale de la bible est écrite en français | BC61: 1 | BM61: =IF(BW61=TRUE,1,0) -> 0 | BW61: FALSE
AC63: ­ Le jeu vidéo est édité dans au moins 3 langues en vigueur dans l'Union européenne : | BC63: 1 | BM63: =IF(BW63=TRUE,1,0) -> 0 | BW63: FALSE
AD65: Langue 1 : | AG65: =#REF! -> #REF!
AD67: Langue 2 : | AG67: =#REF! -> #REF!
AD69: Langue 3 : | AG69: =#REF! -> #REF!
AC71: ­ Traitement de problématiques politiques, sociales ou culturelles ou de valeurs spécifiques | BC71: 1 | BM71: =IF(BW71=TRUE,1,0) -> 0 | BW71: FALSE
AC72: aux sociétés européennes
AB74: Localisation des dépenses et nationalité des auteurs et collaborateurs de création
AC76: ­ 80% des dépenses de développement réalisées en France et en Europe : | BC76: 1 | BM76: =IF(BW76=TRUE,1,0) -> 0 | BW76: FALSE
AD78: Montant des dépenses en France et en Europe : | AO78: =#REF!+#REF! -> #REF!
AD80: Coût total de développement : | AO80: =#REF! -> #REF!
...
